<sdf version='1.11'>
  <model name='h1_description'>
    <plugin
      filename="gz-unitree"
      name="gz::sim::systems::UnitreePlugin">
    </plugin>
    <link name='pelvis'>
      <inertial>
        <pose>0.0097494027875498351 0.001674253124267095 0.17464395412469139 0 0 0</pose>
        <mass>29.847000000000001</mass>
        <inertia>
          <ixx>1.3276870668877401</ixx>
          <ixy>1.2308145851059681e-05</ixy>
          <ixz>0.01737641704017864</ixz>
          <iyy>0.96072171900908165</iyy>
          <iyz>-0.0021968257473229062</iyz>
          <izz>0.53834352817005704</izz>
        </inertia>
      </inertial>
      <collision name='pelvis_collision'>
        <pose>0 0 0 0 0 0</pose>
        <geometry>
          <mesh>
            <scale>1 1 1</scale>
            <uri>../meshes/pelvis.STL</uri>
          </mesh>
        </geometry>
      </collision>
      <collision name='pelvis_fixed_joint_lump__torso_link_collision_1'>
        <pose>0 0 0 0 0 0</pose>
        <geometry>
          <mesh>
            <scale>1 1 1</scale>
            <uri>../meshes/torso_link.STL</uri>
          </mesh>
        </geometry>
      </collision>
      <collision name='pelvis_fixed_joint_lump__left_shoulder_pitch_link_collision_2'>
        <pose>0.0054999999999999997 0.15534999999999999 0.42998999999999998 0.43633 0 0</pose>
        <geometry>
          <mesh>
            <scale>1 1 1</scale>
            <uri>../meshes/left_shoulder_pitch_link.STL</uri>
          </mesh>
        </geometry>
      </collision>
      <collision name='pelvis_fixed_joint_lump__left_shoulder_roll_link_collision_3'>
        <pose>0 0.21352961192699671 0.43891371873290869 0 0 0</pose>
        <geometry>
          <mesh>
            <scale>1 1 1</scale>
            <uri>../meshes/left_shoulder_roll_link.STL</uri>
          </mesh>
        </geometry>
      </collision>
      <collision name='pelvis_fixed_joint_lump__left_shoulder_yaw_link_collision_4'>
        <pose>0 0.21352961192699671 0.30461371873290871 0 0 0</pose>
        <geometry>
          <mesh>
            <scale>1 1 1</scale>
            <uri>../meshes/left_shoulder_yaw_link.STL</uri>
          </mesh>
        </geometry>
      </collision>
      <collision name='pelvis_fixed_joint_lump__left_elbow_link_collision_5'>
        <pose>0.018499999999999999 0.21352961192699671 0.10661371873290861 0 0 0</pose>
        <geometry>
          <mesh>
            <scale>1 1 1</scale>
            <uri>../meshes/left_elbow_link.STL</uri>
          </mesh>
        </geometry>
      </collision>
      <collision name='pelvis_fixed_joint_lump__right_shoulder_pitch_link_collision_6'>
        <pose>0.0054999999999999997 -0.15534999999999999 0.42998999999999998 -0.43633 0 0</pose>
        <geometry>
          <mesh>
            <scale>1 1 1</scale>
            <uri>../meshes/right_shoulder_pitch_link.STL</uri>
          </mesh>
        </geometry>
      </collision>
      <collision name='pelvis_fixed_joint_lump__right_shoulder_roll_link_collision_7'>
        <pose>0 -0.21352961192699671 0.43891371873290869 0 0 0</pose>
        <geometry>
          <mesh>
            <scale>1 1 1</scale>
            <uri>../meshes/right_shoulder_roll_link.STL</uri>
          </mesh>
        </geometry>
      </collision>
      <collision name='pelvis_fixed_joint_lump__right_shoulder_yaw_link_collision_8'>
        <pose>0 -0.21352961192699671 0.30461371873290871 0 0 0</pose>
        <geometry>
          <mesh>
            <scale>1 1 1</scale>
            <uri>../meshes/right_shoulder_yaw_link.STL</uri>
          </mesh>
        </geometry>
      </collision>
      <collision name='pelvis_fixed_joint_lump__right_elbow_link_collision_9'>
        <pose>0.018499999999999999 -0.21352961192699671 0.10661371873290861 0 0 0</pose>
        <geometry>
          <mesh>
            <scale>1 1 1</scale>
            <uri>../meshes/right_elbow_link.STL</uri>
          </mesh>
        </geometry>
      </collision>
      <visual name='pelvis_visual'>
        <pose>0 0 0 0 0 0</pose>
        <geometry>
          <mesh>
            <scale>1 1 1</scale>
            <uri>../meshes/pelvis.STL</uri>
          </mesh>
        </geometry>
        <material>
          <diffuse>0.125 0.125 0.125 1</diffuse>
          <ambient>0.125 0.125 0.125 1</ambient>
        </material>
      </visual>
      <visual name='pelvis_fixed_joint_lump__torso_link_visual_1'>
        <pose>0 0 0 0 0 0</pose>
        <geometry>
          <mesh>
            <scale>1 1 1</scale>
            <uri>../meshes/torso_link.STL</uri>
          </mesh>
        </geometry>
        <material>
          <diffuse>0.125 0.125 0.125 1</diffuse>
          <ambient>0.125 0.125 0.125 1</ambient>
        </material>
      </visual>
      <visual name='pelvis_fixed_joint_lump__left_shoulder_pitch_link_visual_2'>
        <pose>0.0054999999999999997 0.15534999999999999 0.42998999999999998 0.43633 0 0</pose>
        <geometry>
          <mesh>
            <scale>1 1 1</scale>
            <uri>../meshes/left_shoulder_pitch_link.STL</uri>
          </mesh>
        </geometry>
        <material>
          <diffuse>0.125 0.125 0.125 1</diffuse>
          <ambient>0.125 0.125 0.125 1</ambient>
        </material>
      </visual>
      <visual name='pelvis_fixed_joint_lump__left_shoulder_roll_link_visual_3'>
        <pose>0 0.21352961192699671 0.43891371873290869 0 0 0</pose>
        <geometry>
          <mesh>
            <scale>1 1 1</scale>
            <uri>../meshes/left_shoulder_roll_link.STL</uri>
          </mesh>
        </geometry>
        <material>
          <diffuse>0.125 0.125 0.125 1</diffuse>
          <ambient>0.125 0.125 0.125 1</ambient>
        </material>
      </visual>
      <visual name='pelvis_fixed_joint_lump__left_shoulder_yaw_link_visual_4'>
        <pose>0 0.21352961192699671 0.30461371873290871 0 0 0</pose>
        <geometry>
          <mesh>
            <scale>1 1 1</scale>
            <uri>../meshes/left_shoulder_yaw_link.STL</uri>
          </mesh>
        </geometry>
        <material>
          <diffuse>0.125 0.125 0.125 1</diffuse>
          <ambient>0.125 0.125 0.125 1</ambient>
        </material>
      </visual>
      <visual name='pelvis_fixed_joint_lump__left_elbow_link_visual_5'>
        <pose>0.018499999999999999 0.21352961192699671 0.10661371873290861 0 0 0</pose>
        <geometry>
          <mesh>
            <scale>1 1 1</scale>
            <uri>../meshes/left_elbow_link.STL</uri>
          </mesh>
        </geometry>
        <material>
          <diffuse>0.125 0.125 0.125 1</diffuse>
          <ambient>0.125 0.125 0.125 1</ambient>
        </material>
      </visual>
      <visual name='pelvis_fixed_joint_lump__logo_link_visual_6'>
        <pose>0 0 0 0 0 0</pose>
        <geometry>
          <mesh>
            <scale>1 1 1</scale>
            <uri>../meshes/logo_link.STL</uri>
          </mesh>
        </geometry>
        <material>
          <diffuse>1 1 1 1</diffuse>
          <ambient>1 1 1 1</ambient>
        </material>
      </visual>
      <visual name='pelvis_fixed_joint_lump__right_shoulder_pitch_link_visual_7'>
        <pose>0.0054999999999999997 -0.15534999999999999 0.42998999999999998 -0.43633 0 0</pose>
        <geometry>
          <mesh>
            <scale>1 1 1</scale>
            <uri>../meshes/right_shoulder_pitch_link.STL</uri>
          </mesh>
        </geometry>
        <material>
          <diffuse>0.125 0.125 0.125 1</diffuse>
          <ambient>0.125 0.125 0.125 1</ambient>
        </material>
      </visual>
      <visual name='pelvis_fixed_joint_lump__right_shoulder_roll_link_visual_8'>
        <pose>0 -0.21352961192699671 0.43891371873290869 0 0 0</pose>
        <geometry>
          <mesh>
            <scale>1 1 1</scale>
            <uri>../meshes/right_shoulder_roll_link.STL</uri>
          </mesh>
        </geometry>
        <material>
          <diffuse>0.125 0.125 0.125 1</diffuse>
          <ambient>0.125 0.125 0.125 1</ambient>
        </material>
      </visual>
      <visual name='pelvis_fixed_joint_lump__right_shoulder_yaw_link_visual_9'>
        <pose>0 -0.21352961192699671 0.30461371873290871 0 0 0</pose>
        <geometry>
          <mesh>
            <scale>1 1 1</scale>
            <uri>../meshes/right_shoulder_yaw_link.STL</uri>
          </mesh>
        </geometry>
        <material>
          <diffuse>0.125 0.125 0.125 1</diffuse>
          <ambient>0.125 0.125 0.125 1</ambient>
        </material>
      </visual>
      <visual name='pelvis_fixed_joint_lump__right_elbow_link_visual_10'>
        <pose>0.018499999999999999 -0.21352961192699671 0.10661371873290861 0 0 0</pose>
        <geometry>
          <mesh>
            <scale>1 1 1</scale>
            <uri>../meshes/right_elbow_link.STL</uri>
          </mesh>
        </geometry>
        <material>
          <diffuse>0.125 0.125 0.125 1</diffuse>
          <ambient>0.125 0.125 0.125 1</ambient>
        </material>
      </visual>
    </link>
    <joint name='left_hip_yaw_joint' type='revolute'>
      <pose relative_to='pelvis'>0 0.087499999999999994 -0.17419999999999999 0 0 0</pose>
      <parent>pelvis</parent>
      <child>left_hip_yaw_link</child>
      <axis>
        <xyz>0 0 1</xyz>
        <limit>
          <lower>-0.42999999999999999</lower>
          <upper>0.42999999999999999</upper>
          <effort>200</effort>
          <velocity>23</velocity>
        </limit>
        <dynamics>
          <spring_reference>0</spring_reference>
          <spring_stiffness>0</spring_stiffness>
        </dynamics>
      </axis>
    </joint>
    <link name='left_hip_yaw_link'>
      <pose relative_to='left_hip_yaw_joint'>0 0 0 0 0 0</pose>
      <inertial>
        <pose>-0.049230000000000003 0.0001 0.0071999999999999998 0 0 0</pose>
        <mass>2.2440000000000002</mass>
        <inertia>
          <ixx>0.0025731</ixx>
          <ixy>9.1589999999999999e-06</ixy>
          <ixz>-0.00051948000000000001</ixz>
          <iyy>0.0030444000000000001</iyy>
          <iyz>1.9489999999999999e-06</iyz>
          <izz>0.0022883000000000001</izz>
        </inertia>
      </inertial>
      <visual name='left_hip_yaw_link_visual'>
        <pose>0 0 0 0 0 0</pose>
        <geometry>
          <mesh>
            <scale>1 1 1</scale>
            <uri>../meshes/left_hip_yaw_link.STL</uri>
          </mesh>
        </geometry>
        <material>
          <diffuse>0.125 0.125 0.125 1</diffuse>
          <ambient>0.125 0.125 0.125 1</ambient>
        </material>
      </visual>
    </link>
    <joint name='left_hip_roll_joint' type='revolute'>
      <pose relative_to='left_hip_yaw_link'>0.039468000000000003 0 0 0 0 0</pose>
      <parent>left_hip_yaw_link</parent>
      <child>left_hip_roll_link</child>
      <axis>
        <xyz>1 0 0</xyz>
        <limit>
          <lower>-0.42999999999999999</lower>
          <upper>0.42999999999999999</upper>
          <effort>200</effort>
          <velocity>23</velocity>
        </limit>
        <dynamics>
          <spring_reference>0</spring_reference>
          <spring_stiffness>0</spring_stiffness>
        </dynamics>
      </axis>
    </joint>
    <link name='left_hip_roll_link'>
      <pose relative_to='left_hip_roll_joint'>0 0 0 0 0 0</pose>
      <inertial>
        <pose>-0.0057999999999999996 -0.0031900000000000001 -9.0000000000000006e-05 0 0 0</pose>
        <mass>2.2320000000000002</mass>
        <inertia>
          <ixx>0.0020603000000000002</ixx>
          <ixy>3.2115e-05</ixy>
          <ixz>2.8779999999999998e-06</ixz>
          <iyy>0.0022482000000000001</iyy>
          <iyz>-7.8129999999999996e-06</iyz>
          <izz>0.0024323000000000001</izz>
        </inertia>
      </inertial>
      <collision name='left_hip_roll_link_collision'>
        <pose>0 0 0 0 0 0</pose>
        <geometry>
          <mesh>
            <scale>1 1 1</scale>
            <uri>../meshes/left_hip_roll_link.STL</uri>
          </mesh>
        </geometry>
      </collision>
      <visual name='left_hip_roll_link_visual'>
        <pose>0 0 0 0 0 0</pose>
        <geometry>
          <mesh>
            <scale>1 1 1</scale>
            <uri>../meshes/left_hip_roll_link.STL</uri>
          </mesh>
        </geometry>
        <material>
          <diffuse>0.125 0.125 0.125 1</diffuse>
          <ambient>0.125 0.125 0.125 1</ambient>
        </material>
      </visual>
    </link>
    <joint name='left_hip_pitch_joint' type='revolute'>
      <pose relative_to='left_hip_roll_link'>0 0.11536 0 0 0 0</pose>
      <parent>left_hip_roll_link</parent>
      <child>left_hip_pitch_link</child>
      <axis>
        <xyz>0 1 0</xyz>
        <limit>
          <lower>-1.5700000000000001</lower>
          <upper>1.5700000000000001</upper>
          <effort>200</effort>
          <velocity>23</velocity>
        </limit>
        <dynamics>
          <spring_reference>0</spring_reference>
          <spring_stiffness>0</spring_stiffness>
        </dynamics>
      </axis>
    </joint>
    <link name='left_hip_pitch_link'>
      <pose relative_to='left_hip_pitch_joint'>0 0 0 0 0 0</pose>
      <inertial>
        <pose>0.0074599999999999996 -0.023460000000000002 -0.081930000000000003 0 0 0</pose>
        <mass>4.1520000000000001</mass>
        <inertia>
          <ixx>0.082617999999999997</ixx>
          <ixy>-0.00066653999999999997</ixy>
          <ixz>0.0040724999999999997</ixz>
          <iyy>0.081578999999999999</iyy>
          <iyz>0.0072024000000000003</iyz>
          <izz>0.0060080999999999997</izz>
        </inertia>
      </inertial>
      <collision name='left_hip_pitch_link_collision'>
        <pose>0 0 0 0 0 0</pose>
        <geometry>
          <mesh>
            <scale>1 1 1</scale>
            <uri>../meshes/left_hip_pitch_link.STL</uri>
          </mesh>
        </geometry>
      </collision>
      <visual name='left_hip_pitch_link_visual'>
        <pose>0 0 0 0 0 0</pose>
        <geometry>
          <mesh>
            <scale>1 1 1</scale>
            <uri>../meshes/left_hip_pitch_link.STL</uri>
          </mesh>
        </geometry>
        <material>
          <diffuse>0.125 0.125 0.125 1</diffuse>
          <ambient>0.125 0.125 0.125 1</ambient>
        </material>
      </visual>
    </link>
    <joint name='left_knee_joint' type='revolute'>
      <pose relative_to='left_hip_pitch_link'>0 0 -0.40000000000000002 0 0 0</pose>
      <parent>left_hip_pitch_link</parent>
      <child>left_knee_link</child>
      <axis>
        <xyz>0 1 0</xyz>
        <limit>
          <lower>-0.26000000000000001</lower>
          <upper>2.0499999999999998</upper>
          <effort>300</effort>
          <velocity>14</velocity>
        </limit>
        <dynamics>
          <spring_reference>0</spring_reference>
          <spring_stiffness>0</spring_stiffness>
        </dynamics>
      </axis>
    </joint>
    <link name='left_knee_link'>
      <pose relative_to='left_knee_joint'>0 0 0 0 0 0</pose>
      <inertial>
        <pose>-0.0013600000000000001 -0.0051200000000000004 -0.1384 0 0 0</pose>
        <mass>1.7210000000000001</mass>
        <inertia>
          <ixx>0.012205000000000001</ixx>
          <ixy>-6.8430999999999996e-05</ixy>
          <ixz>0.0010862000000000001</ixz>
          <iyy>0.012508999999999999</iyy>
          <iyz>0.00022549000000000001</iyz>
          <izz>0.0020628999999999999</izz>
        </inertia>
      </inertial>
      <collision name='left_knee_link_collision'>
        <pose>0 0 0 0 0 0</pose>
        <geometry>
          <mesh>
            <scale>1 1 1</scale>
            <uri>../meshes/left_knee_link.STL</uri>
          </mesh>
        </geometry>
      </collision>
      <visual name='left_knee_link_visual'>
        <pose>0 0 0 0 0 0</pose>
        <geometry>
          <mesh>
            <scale>1 1 1</scale>
            <uri>../meshes/left_knee_link.STL</uri>
          </mesh>
        </geometry>
        <material>
          <diffuse>0.125 0.125 0.125 1</diffuse>
          <ambient>0.125 0.125 0.125 1</ambient>
        </material>
      </visual>
    </link>
    <joint name='left_ankle_joint' type='revolute'>
      <pose relative_to='left_knee_link'>0 0 -0.40000000000000002 0 0 0</pose>
      <parent>left_knee_link</parent>
      <child>left_ankle_link</child>
      <axis>
        <xyz>0 1 0</xyz>
        <limit>
          <lower>-0.87</lower>
          <upper>0.52000000000000002</upper>
          <effort>40</effort>
          <velocity>9</velocity>
        </limit>
        <dynamics>
          <spring_reference>0</spring_reference>
          <spring_stiffness>0</spring_stiffness>
        </dynamics>
      </axis>
    </joint>
    <link name='left_ankle_link'>
      <pose relative_to='left_ankle_joint'>0 0 0 0 0 0</pose>
      <inertial>
        <pose>0.048568 0 -0.045608999999999997 0 0 0</pose>
        <mass>0.55244800000000005</mass>
        <inertia>
          <ixx>0.01</ixx>
          <ixy>0</ixy>
          <ixz>0.00014300000000000001</ixz>
          <iyy>0.01</iyy>
          <iyz>0</iyz>
          <izz>0.01</izz>
        </inertia>
      </inertial>
      <collision name='left_ankle_link_collision'>
        <pose>0 0 0 0 0 0</pose>
        <geometry>
          <mesh>
            <scale>1 1 1</scale>
            <uri>../meshes/left_ankle_link.STL</uri>
          </mesh>
        </geometry>
      </collision>
      <visual name='left_ankle_link_visual'>
        <pose>0 0 0 0 0 0</pose>
        <geometry>
          <mesh>
            <scale>1 1 1</scale>
            <uri>../meshes/left_ankle_link.STL</uri>
          </mesh>
        </geometry>
        <material>
          <diffuse>0.125 0.125 0.125 1</diffuse>
          <ambient>0.125 0.125 0.125 1</ambient>
        </material>
      </visual>
    </link>
    <joint name='right_hip_yaw_joint' type='revolute'>
      <pose relative_to='pelvis'>0 -0.087499999999999994 -0.17419999999999999 0 0 0</pose>
      <parent>pelvis</parent>
      <child>right_hip_yaw_link</child>
      <axis>
        <xyz>0 0 1</xyz>
        <limit>
          <lower>-0.42999999999999999</lower>
          <upper>0.42999999999999999</upper>
          <effort>200</effort>
          <velocity>23</velocity>
        </limit>
        <dynamics>
          <spring_reference>0</spring_reference>
          <spring_stiffness>0</spring_stiffness>
        </dynamics>
      </axis>
    </joint>
    <link name='right_hip_yaw_link'>
      <pose relative_to='right_hip_yaw_joint'>0 0 0 0 0 0</pose>
      <inertial>
        <pose>-0.049230000000000003 -0.0001 0.0071999999999999998 0 0 0</pose>
        <mass>2.2440000000000002</mass>
        <inertia>
          <ixx>0.0025731</ixx>
          <ixy>-9.1589999999999999e-06</ixy>
          <ixz>-0.00051948000000000001</ixz>
          <iyy>0.0030444000000000001</iyy>
          <iyz>-1.9489999999999999e-06</iyz>
          <izz>0.0022883000000000001</izz>
        </inertia>
      </inertial>
      <visual name='right_hip_yaw_link_visual'>
        <pose>0 0 0 0 0 0</pose>
        <geometry>
          <mesh>
            <scale>1 1 1</scale>
            <uri>../meshes/right_hip_yaw_link.STL</uri>
          </mesh>
        </geometry>
        <material>
          <diffuse>0.125 0.125 0.125 1</diffuse>
          <ambient>0.125 0.125 0.125 1</ambient>
        </material>
      </visual>
    </link>
    <joint name='right_hip_roll_joint' type='revolute'>
      <pose relative_to='right_hip_yaw_link'>0.039468000000000003 0 0 0 0 0</pose>
      <parent>right_hip_yaw_link</parent>
      <child>right_hip_roll_link</child>
      <axis>
        <xyz>1 0 0</xyz>
        <limit>
          <lower>-0.42999999999999999</lower>
          <upper>0.42999999999999999</upper>
          <effort>200</effort>
          <velocity>23</velocity>
        </limit>
        <dynamics>
          <spring_reference>0</spring_reference>
          <spring_stiffness>0</spring_stiffness>
        </dynamics>
      </axis>
    </joint>
    <link name='right_hip_roll_link'>
      <pose relative_to='right_hip_roll_joint'>0 0 0 0 0 0</pose>
      <inertial>
        <pose>-0.0057999999999999996 0.0031900000000000001 -9.0000000000000006e-05 0 0 0</pose>
        <mass>2.2320000000000002</mass>
        <inertia>
          <ixx>0.0020603000000000002</ixx>
          <ixy>-3.2115e-05</ixy>
          <ixz>2.8779999999999998e-06</ixz>
          <iyy>0.0022482000000000001</iyy>
          <iyz>7.8129999999999996e-06</iyz>
          <izz>0.0024323000000000001</izz>
        </inertia>
      </inertial>
      <collision name='right_hip_roll_link_collision'>
        <pose>0 0 0 0 0 0</pose>
        <geometry>
          <mesh>
            <scale>1 1 1</scale>
            <uri>../meshes/right_hip_roll_link.STL</uri>
          </mesh>
        </geometry>
      </collision>
      <visual name='right_hip_roll_link_visual'>
        <pose>0 0 0 0 0 0</pose>
        <geometry>
          <mesh>
            <scale>1 1 1</scale>
            <uri>../meshes/right_hip_roll_link.STL</uri>
          </mesh>
        </geometry>
        <material>
          <diffuse>0.125 0.125 0.125 1</diffuse>
          <ambient>0.125 0.125 0.125 1</ambient>
        </material>
      </visual>
    </link>
    <joint name='right_hip_pitch_joint' type='revolute'>
      <pose relative_to='right_hip_roll_link'>0 -0.11536 0 0 0 0</pose>
      <parent>right_hip_roll_link</parent>
      <child>right_hip_pitch_link</child>
      <axis>
        <xyz>0 1 0</xyz>
        <limit>
          <lower>-1.5700000000000001</lower>
          <upper>1.5700000000000001</upper>
          <effort>200</effort>
          <velocity>23</velocity>
        </limit>
        <dynamics>
          <spring_reference>0</spring_reference>
          <spring_stiffness>0</spring_stiffness>
        </dynamics>
      </axis>
    </joint>
    <link name='right_hip_pitch_link'>
      <pose relative_to='right_hip_pitch_joint'>0 0 0 0 0 0</pose>
      <inertial>
        <pose>0.0074599999999999996 0.023460000000000002 -0.081930000000000003 0 0 0</pose>
        <mass>4.1520000000000001</mass>
        <inertia>
          <ixx>0.082617999999999997</ixx>
          <ixy>0.00066653999999999997</ixy>
          <ixz>0.0040724999999999997</ixz>
          <iyy>0.081578999999999999</iyy>
          <iyz>-0.0072024000000000003</iyz>
          <izz>0.0060080999999999997</izz>
        </inertia>
      </inertial>
      <collision name='right_hip_pitch_link_collision'>
        <pose>0 0 0 0 0 0</pose>
        <geometry>
          <mesh>
            <scale>1 1 1</scale>
            <uri>../meshes/right_hip_pitch_link.STL</uri>
          </mesh>
        </geometry>
      </collision>
      <visual name='right_hip_pitch_link_visual'>
        <pose>0 0 0 0 0 0</pose>
        <geometry>
          <mesh>
            <scale>1 1 1</scale>
            <uri>../meshes/right_hip_pitch_link.STL</uri>
          </mesh>
        </geometry>
        <material>
          <diffuse>0.125 0.125 0.125 1</diffuse>
          <ambient>0.125 0.125 0.125 1</ambient>
        </material>
      </visual>
    </link>
    <joint name='right_knee_joint' type='revolute'>
      <pose relative_to='right_hip_pitch_link'>0 0 -0.40000000000000002 0 0 0</pose>
      <parent>right_hip_pitch_link</parent>
      <child>right_knee_link</child>
      <axis>
        <xyz>0 1 0</xyz>
        <limit>
          <lower>-0.26000000000000001</lower>
          <upper>2.0499999999999998</upper>
          <effort>300</effort>
          <velocity>14</velocity>
        </limit>
        <dynamics>
          <spring_reference>0</spring_reference>
          <spring_stiffness>0</spring_stiffness>
        </dynamics>
      </axis>
    </joint>
    <link name='right_knee_link'>
      <pose relative_to='right_knee_joint'>0 0 0 0 0 0</pose>
      <inertial>
        <pose>-0.0013600000000000001 0.0051200000000000004 -0.1384 0 0 0</pose>
        <mass>1.7210000000000001</mass>
        <inertia>
          <ixx>0.012205000000000001</ixx>
          <ixy>6.8430999999999996e-05</ixy>
          <ixz>0.0010862000000000001</ixz>
          <iyy>0.012508999999999999</iyy>
          <iyz>-0.00022549000000000001</iyz>
          <izz>0.0020628999999999999</izz>
        </inertia>
      </inertial>
      <collision name='right_knee_link_collision'>
        <pose>0 0 0 0 0 0</pose>
        <geometry>
          <mesh>
            <scale>1 1 1</scale>
            <uri>../meshes/right_knee_link.STL</uri>
          </mesh>
        </geometry>
      </collision>
      <visual name='right_knee_link_visual'>
        <pose>0 0 0 0 0 0</pose>
        <geometry>
          <mesh>
            <scale>1 1 1</scale>
            <uri>../meshes/right_knee_link.STL</uri>
          </mesh>
        </geometry>
        <material>
          <diffuse>0.125 0.125 0.125 1</diffuse>
          <ambient>0.125 0.125 0.125 1</ambient>
        </material>
      </visual>
    </link>
    <joint name='right_ankle_joint' type='revolute'>
      <pose relative_to='right_knee_link'>0 0 -0.40000000000000002 0 0 0</pose>
      <parent>right_knee_link</parent>
      <child>right_ankle_link</child>
      <axis>
        <xyz>0 1 0</xyz>
        <limit>
          <lower>-0.87</lower>
          <upper>0.52000000000000002</upper>
          <effort>40</effort>
          <velocity>9</velocity>
        </limit>
        <dynamics>
          <spring_reference>0</spring_reference>
          <spring_stiffness>0</spring_stiffness>
        </dynamics>
      </axis>
    </joint>
    <link name='right_ankle_link'>
      <pose relative_to='right_ankle_joint'>0 0 0 0 0 0</pose>
      <inertial>
        <pose>0.048568 0 -0.045608999999999997 0 0 0</pose>
        <mass>0.55244800000000005</mass>
        <inertia>
          <ixx>0.01</ixx>
          <ixy>0</ixy>
          <ixz>0.00014300000000000001</ixz>
          <iyy>0.01</iyy>
          <iyz>0</iyz>
          <izz>0.01</izz>
        </inertia>
      </inertial>
      <collision name='right_ankle_link_collision'>
        <pose>0 0 0 0 0 0</pose>
        <geometry>
          <mesh>
            <scale>1 1 1</scale>
            <uri>../meshes/right_ankle_link.STL</uri>
          </mesh>
        </geometry>
      </collision>
      <visual name='right_ankle_link_visual'>
        <pose>0 0 0 0 0 0</pose>
        <geometry>
          <mesh>
            <scale>1 1 1</scale>
            <uri>../meshes/right_ankle_link.STL</uri>
          </mesh>
        </geometry>
        <material>
          <diffuse>0.125 0.125 0.125 1</diffuse>
          <ambient>0.125 0.125 0.125 1</ambient>
        </material>
      </visual>
    </link>
    <frame name='imu_joint' attached_to='torso_link'>
      <pose>-0.044519999999999997 -0.01891 0.27755999999999997 0 0 0</pose>
    </frame>
    <frame name='imu_link' attached_to='imu_joint'>
      <pose>0 0 0 0 0 0</pose>
    </frame>
    <frame name='left_elbow_joint' attached_to='left_shoulder_yaw_link'>
      <pose>0.018499999999999999 0 -0.19800000000000001 0 0 0</pose>
    </frame>
    <frame name='left_elbow_link' attached_to='left_elbow_joint'>
      <pose>0 0 0 0 0 0</pose>
    </frame>
    <frame name='left_shoulder_yaw_joint' attached_to='left_shoulder_roll_link'>
      <pose>0 0 -0.1343 0 0 0</pose>
    </frame>
    <frame name='left_shoulder_yaw_link' attached_to='left_shoulder_yaw_joint'>
      <pose>0 0 0 0 0 0</pose>
    </frame>
    <frame name='left_shoulder_roll_joint' attached_to='left_shoulder_pitch_link'>
      <pose>-0.0054999999999999997 0.056500000000000002 -0.016500000000000001 -0.43633 0 0</pose>
    </frame>
    <frame name='left_shoulder_roll_link' attached_to='left_shoulder_roll_joint'>
      <pose>0 0 0 0 0 0</pose>
    </frame>
    <frame name='left_shoulder_pitch_joint' attached_to='torso_link'>
      <pose>0.0054999999999999997 0.15534999999999999 0.42998999999999998 0.43633 0 0</pose>
    </frame>
    <frame name='left_shoulder_pitch_link' attached_to='left_shoulder_pitch_joint'>
      <pose>0 0 0 0 0 0</pose>
    </frame>
    <frame name='logo_joint' attached_to='torso_link'>
      <pose>0 0 0 0 0 0</pose>
    </frame>
    <frame name='logo_link' attached_to='logo_joint'>
      <pose>0 0 0 0 0 0</pose>
    </frame>
    <frame name='right_elbow_joint' attached_to='right_shoulder_yaw_link'>
      <pose>0.018499999999999999 0 -0.19800000000000001 0 0 0</pose>
    </frame>
    <frame name='right_elbow_link' attached_to='right_elbow_joint'>
      <pose>0 0 0 0 0 0</pose>
    </frame>
    <frame name='right_shoulder_yaw_joint' attached_to='right_shoulder_roll_link'>
      <pose>0 0 -0.1343 0 0 0</pose>
    </frame>
    <frame name='right_shoulder_yaw_link' attached_to='right_shoulder_yaw_joint'>
      <pose>0 0 0 0 0 0</pose>
    </frame>
    <frame name='right_shoulder_roll_joint' attached_to='right_shoulder_pitch_link'>
      <pose>-0.0054999999999999997 -0.056500000000000002 -0.016500000000000001 0.43633 0 0</pose>
    </frame>
    <frame name='right_shoulder_roll_link' attached_to='right_shoulder_roll_joint'>
      <pose>0 0 0 0 0 0</pose>
    </frame>
    <frame name='right_shoulder_pitch_joint' attached_to='torso_link'>
      <pose>0.0054999999999999997 -0.15534999999999999 0.42998999999999998 -0.43633 0 0</pose>
    </frame>
    <frame name='right_shoulder_pitch_link' attached_to='right_shoulder_pitch_joint'>
      <pose>0 0 0 0 0 0</pose>
    </frame>
    <frame name='torso_joint' attached_to='pelvis'>
      <pose>0 0 0 0 0 0</pose>
    </frame>
    <frame name='torso_link' attached_to='torso_joint'>
      <pose>0 0 0 0 0 0</pose>
    </frame>
  </model>
</sdf>
